Workbook

Sheet Зачернение
A1: Схемы зачернений (проведение предупредительных противопаводковых мероприятий по ослаблению прочности льда на затороопасных участках рек)
A2: № | B2: Наименование защищаемого населенного пункта | C2: Дата (дд.мм.гггг) | D2: Наименование реки | E2: Наименование района | F2: Наименование населенного пункта | G2: ОКТМО | H2: Количество полос | I2: Ширина, м | J2: Протяженность, м | K2: Площадь, м2 | L2: Объем зачерняющего материала, м3 | M2: Глубина протаивания льда, см | N2: Геопозиция (широта) | O2: Геопозиция (долгота) | P2: Местность | Q2: Ответственный
A3: 1 | B3: =VLOOKUP(G3,ОКТМО!B:M,12,0) -> Чагда | D3: Алдан | E3: =VLOOKUP(G3,ОКТМО!B:M,6,0) -> Алданский муниципальный район | F3: =VLOOKUP(G3,ОКТМО!B:M,12,0) -> Чагда | G3: 98603460101 | H3: 2 | I3: 20 | J3: 1000 | K3: =I3*J3*H3 -> 40000 | L3: 80 | N3: 58.72149334 | O3: 130.61732873 | P3: выше н.п. Чагда | Q3: ЛБВУ ФАВР
A4: 2 | B4: =VLOOKUP(G4,ОКТМО!B:M,12,0) -> Чагда | D4: Алдан | E4: =VLOOKUP(G4,ОКТМО!B:M,6,0) -> Алданский муниципальный район | F4: =VLOOKUP(G4,ОКТМО!B:M,12,0) -> Чагда | G4: 98603460101 | H4: 2 | I4: 20 | J4: 1000 | K4: =I4*J4*H4 -> 40000 | L4: 80 | N4: 58.78355898 | O4: 130.60016259 | P4: у о. Первомайский | Q4: ЛБВУ ФАВР
A5: 3 | B5: =VLOOKUP(G5,ОКТМО!B:M,12,0) -> Белькачи | D5: Алдан | E5: =VLOOKUP(G5,ОКТМО!B:M,6,0) -> Усть-Майский муниципальный район | F5: =VLOOKUP(G5,ОКТМО!B:M,12,0) -> Белькачи | G5: 98654405101 | H5: 2 | I5: 20 | J5: 2000 | K5: =I5*J5*H5 -> 80000 | L5: 160 | N5: 59.14552075 | O5: 131.93019208 | P5: у о. Бур-Ары | Q5: ЛБВУ ФАВР
A6: 4 | B6: =VLOOKUP(G6,ОКТМО!B:M,12,0) -> Белькачи | D6: Алдан | E6: =VLOOKUP(G6,ОКТМО!B:M,6,0) -> Усть-Майский муниципальный район | F6: =VLOOKUP(G6,ОКТМО!B:M,12,0) -> Белькачи | G6: 98654405101 | H6: 2 | I6: 20 | J6: 1000 | K6: =I6*J6*H6 -> 40000 | L6: 80 | N6: 59.14481644 | O6: 132.07095441 | P6: в 12км ниже н.п. Белькачи | Q6: ЛБВУ ФАВР
A7: 5 | B7: =VLOOKUP(G7,ОКТМО!B:M,12,0) -> Эжанцы | D7: Алдан | E7: =VLOOKUP(G7,ОКТМО!B:M,6,0) -> Усть-Майский муниципальный район | F7: =VLOOKUP(G7,ОКТМО!B:M,12,0) -> Эжанцы | G7: 98654425101 | H7: 2 | I7: 20 | J7: 2000 | K7: =I7*J7*H7 -> 80000 | L7: 160 | N7: 60.50585294 | O7: 135.10204457 | P7: ниже н.п. Эжанцы | Q7: ЛБВУ ФАВР
A8: 6 | B8: =VLOOKUP(G8,ОКТМО!B:M,12,0) -> Кюпцы | D8: Алдан | E8: =VLOOKUP(G8,ОКТМО!B:M,6,0) -> Усть-Майский муниципальный район | F8: =VLOOKUP(G8,ОКТМО!B:M,12,0) -> Кюпцы | G8: 98654410101 | H8: 2 | I8: 20 | J8: 2200 | K8: =I8*J8*H8 -> 88000 | L8: 176 | N8: 60.89963345 | O8: 135.35176073 | P8: у о. Тит-Ары | Q8: ЛБВУ ФАВР
A9: 7 | B9: =VLOOKUP(G9,ОКТМО!B:M,12,0) -> Кюпцы | D9: Алдан | E9: =VLOOKUP(G9,ОКТМО!B:M,6,0) -> Усть-Майский муниципальный район | F9: =VLOOKUP(G9,ОКТМО!B:M,12,0) -> Кюпцы | G9: 98654410101 | H9: 2 | I9: 20 | J9: 1000 | K9: =I9*J9*H9 -> 40000 | L9: 80 | N9: 61.00061654 | O9: 135.43085347 | P9: у пер. Ноторские острова | Q9: ЛБВУ ФАВР
A10: 8 | B10: =VLOOKUP(G10,ОКТМО!B:M,12,0) -> Кюпцы | D10: Алдан | E10: =VLOOKUP(G10,ОКТМО!B:M,6,0) -> Усть-Майский муниципальный район | F10: =VLOOKUP(G10,ОКТМО!B:M,12,0) -> Кюпцы | G10: 98654410101 | H10: 2 | I10: 20 | J10: 1500 | K10: =I10*J10*H10 -> 60000 | L10: 120 | N10: 61.09484956 | O10: 135.50089132 | P10: у о. Улахан Отоннуур | Q10: ЛБВУ ФАВР
A11: 9 | B11: =VLOOKUP(G11,ОКТМО!B:M,12,0) -> Кюпцы | D11: Алдан | E11: =VLOOKUP(G11,ОКТМО!B:M,6,0) -> Усть-Майский муниципальный район | F11: =VLOOKUP(G11,ОКТМО!B:M,12,0) -> Кюпцы | G11: 98654410101 | H11: 2 | I11: 20 | J11: 1500 | K11: =I11*J11*H11 -> 60000 | L11: 120 | N11: 61.32250202 | O11: 135.49728129 | P11: уч. Сымнар | Q11: ЛБВУ ФАВР
A12: 10 | B12: =VLOOKUP(G12,ОКТМО!B:M,12,0) -> Хандыга | D12: Алдан | E12: =VLOOKUP(G12,ОКТМО!B:M,6,0) -> Томпонский муниципальный район | F12: =VLOOKUP(G12,ОКТМО!B:M,12,0) -> Хандыга | G12: 98650151051 | H12: 2 | I12: 20 | J12: 1000 | K12: =I12*J12*H12 -> 40000 | L12: 40 | N12: 62.59919178 | O12: 135.27743823 | P12: у о. Арга (перекат Собачий) | Q12: ЛБВУ ФАВР
A13: 11 | B13: =VLOOKUP(G13,ОКТМО!B:M,12,0) -> Хандыга | D13: Алдан | E13: =VLOOKUP(G13,ОКТМО!B:M,6,0) -> Томпонский муниципальный район | F13: =VLOOKUP(G13,ОКТМО!B:M,12,0) -> Хандыга | G13: 98650151051 | H13: 2 | I13: 20 | J13: 1000 | K13: =I13*J13*H13 -> 40000 | L13: 40 | N13: 62.58243892 | O13: 135.21014697 | P13: у о. Арга (перекат Собачий) | Q13: ЛБВУ ФАВР
A14: 12 | B14: =VLOOKUP(G14,ОКТМО!B:M,12,0) -> Кескил | D14: Алдан | E14: =VLOOKUP(G14,ОКТМО!B:M,6,0) -> Томпонский муниципальный район | F14: =VLOOKUP(G14,ОКТМО!B:M,12,0) -> Кескил | G14: 98650430101 | H14: 2 | I14: 20 | J14: 1500 | K14: =I14*J14*H14 -> 60000 | L14: 60 | N14: 62.68549287 | O14: 134.72297199 | P14: у о. Маган | Q14: ЛБВУ ФАВР
... A16: 14 | B16: =VLOOKUP(G16,ОКТМО!B:M,12,0) -> Хара-Алдан | D16: Алдан | E16: =VLOOKUP(G16,ОКТМО!B:M,6,0) -> Таттинский муниципальный район | F16: =VLOOKUP(G16,ОКТМО!B:M,12,0) -> Хара-Алдан | G16: 98604465101 | H16: 2 | I16: 20 | J16: 2000 | K16: =I16*J16*H16 -> 80000 | L16: 80 | N16: 63.34089060 | O16: 133.26350696 | P16: в 8 км. ниже с. Хара-Алдан | Q16: ЛБВУ ФАВР
A17: 15 | B17: =VLOOKUP(G17,ОКТМО!B:M,12,0) -> Сыгыннах | D17: Алдан | E17: =VLOOKUP(G17,ОКТМО!B:M,6,0) -> Намский муниципальный район | F17: =VLOOKUP(G17,ОКТМО!B:M,12,0) -> Сыгыннах | G17: 98635405101 | H17: 2 | I17: 20 | J17: 2000 | K17: =I17*J17*H17 -> 80000 | L17: NULL | N17: 63.45301846 | O17: 129.57625695 | P17: у о. Ходжох | Q17: ЛБВУ ФАВР
A18: 16 | B18: =VLOOKUP(G18,ОКТМО!B:M,12,0) -> Сыгыннах | D18: Алдан | E18: =VLOOKUP(G18,ОКТМО!B:M,6,0) -> Намский муниципальный район | F18: =VLOOKUP(G18,ОКТМО!B:M,12,0) -> Сыгыннах | G18: 98635405101 | H18: 2 | I18: 20 | J18: 2000 | K18: =I18*J18*H18 -> 80000 | L18: NULL | N18: 63.41831961 | O18: 129.71616098 | P18: у о. Сис-Кумах | Q18: ЛБВУ ФАВР
A19: 17 | B19: =VLOOKUP(G19,ОКТМО!B:M,12,0) -> Сыгыннах | D19: Алдан | E19: =VLOOKUP(G19,ОКТМО!B:M,6,0) -> Намский муниципальный район | F19: =VLOOKUP(G19,ОКТМО!B:M,12,0) -> Сыгыннах | G19: 98635405101 | H19: 2 | I19: 20 | J19: 2000 | K19: =I19*J19*H19 -> 80000 | L19: NULL | N19: 63.41463231 | O19: 129.98343774 | P19: у о. Ого-Унуохтаах | Q19: ЛБВУ ФАВР
A20: 18 | B20: =VLOOKUP(G20,ОКТМО!B:M,12,0) -> Верхняя Амга | D20: Амга | E20: =VLOOKUP(G20,ОКТМО!B:M,6,0) -> Алданский муниципальный район | F20: =VLOOKUP(G20,ОКТМО!B:M,12,0) -> Верхняя Амга | G20: 98603105111 | H20: 2 | I20: 20 | J20: 2000 | K20: =I20*J20*H20 -> 80000 | L20: NULL | N20: 59.65822343 | O20: 127.10953626 | P20: р. Курум Кюнкю | Q20: ЛБВУ ФАВР
A21: 19 | B21: =VLOOKUP(G21,ОКТМО!B:M,12,0) -> Верхняя Амга | D21: Амга | E21: =VLOOKUP(G21,ОКТМО!B:M,6,0) -> Алданский муниципальный район | F21: =VLOOKUP(G21,ОКТМО!B:M,12,0) -> Верхняя Амга | G21: 98603105111 | H21: 2 | I21: 20 | J21: 2000 | K21: =I21*J21*H21 -> 80000 | L21: NULL | N21: 59.63037606 | O21: 127.17408094 | P21: р. Курум Арыта | Q21: ЛБВУ ФАВР
A22: 20 | B22: =VLOOKUP(G22,ОКТМО!B:M,12,0) -> Амга | D22: Амга | E22: =VLOOKUP(G22,ОКТМО!B:M,6,0) -> Амгинский муниципальный район | F22: =VLOOKUP(G22,ОКТМО!B:M,12,0) -> Амга | G22: 98608432101 | H22: 2 | I22: 20 | J22: 2000 | K22: =I22*J22*H22 -> 80000 | L22: NULL | N22: 60.85311468 | O22: 131.92317407 | P22: о. Ус-Уэстэх | Q22: ЛБВУ ФАВР
A23: 21 | B23: =VLOOKUP(G23,ОКТМО!B:M,12,0) -> Амга | D23: Амга | E23: =VLOOKUP(G23,ОКТМО!B:M,6,0) -> Амгинский муниципальный район | F23: =VLOOKUP(G23,ОКТМО!B:M,12,0) -> Амга | G23: =98608432101 -> 98608432101 | H23: 2 | I23: 20 | J23: 2000 | K23: =I23*J23*H23 -> 80000 | L23: NULL | N23: 60.86874549 | O23: 132.00883310 | P23: о. Молода | Q23: ЛБВУ ФАВР
A24: 22 | B24: =VLOOKUP(G24,ОКТМО!B:M,12,0) -> Бетюнцы | D24: Амга | E24: =VLOOKUP(G24,ОКТМО!B:M,6,0) -> Амгинский муниципальный район | F24: =VLOOKUP(G24,ОКТМО!B:M,12,0) -> Бетюнцы | G24: 98608440101 | H24: 2 | I24: 20 | J24: 2000 | K24: =I24*J24*H24 -> 80000 | L24: NULL | N24: 60.90707963 | O24: 132.21671503 | P24: о. Уорай (Невезения) | Q24: ЛБВУ ФАВР
A25: 23 | B25: =VLOOKUP(G25,ОКТМО!B:M,12,0) -> Абага | D25: Амга | E25: =VLOOKUP(G25,ОКТМО!B:M,6,0) -> Амгинский муниципальный район | F25: =VLOOKUP(G25,ОКТМО!B:M,12,0) -> Абага | G25: 98608405101 | H25: 2 | I25: 20 | J25: 2000 | K25: =I25*J25*H25 -> 80000 | L25: NULL | N25: 61.00999419 | O25: 132.42828767 | P25: Харчы Хайата | Q25: ЛБВУ ФАВР
A26: 24 | B26: =VLOOKUP(G26,ОКТМО!B:M,12,0) -> Михайловка | D26: Амга | E26: =VLOOKUP(G26,ОКТМО!B:M,6,0) -> Амгинский муниципальный район | F26: =VLOOKUP(G26,ОКТМО!B:M,12,0) -> Михайловка | G26: 98608460101 | H26: 2 | I26: 20 | J26: 1500 | K26: =I26*J26*H26 -> 60000 | L26: NULL | N26: 61.21052784 | O26: 132.60715883 | P26: р. Ксенофонт Арыта | Q26: ЛБВУ ФАВР
A27: 25 | B27: =VLOOKUP(G27,ОКТМО!B:M,12,0) -> Мындагай | D27: Амга | E27: =VLOOKUP(G27,ОКТМО!B:M,6,0) -> Чурапчинский муниципальный район | F27: =VLOOKUP(G27,ОКТМО!B:M,12,0) -> Мындагай | G27: 98658415101 | H27: 2 | I27: 20 | J27: 2000 | K27: =I27*J27*H27 -> 80000 | L27: NULL | N27: 61.66781163 | O27: 133.26530855 | P27: о. Уолала | Q27: ЛБВУ ФАВР
A28: 26 | B28: =VLOOKUP(G28,ОКТМО!B:M,12,0) -> Мындагай | D28: Амга | E28: =VLOOKUP(G28,ОКТМО!B:M,6,0) -> Чурапчинский муниципальный район | F28: =VLOOKUP(G28,ОКТМО!B:M,12,0) -> Мындагай | G28: 98658415101 | H28: 2 | I28: 20 | J28: 2000 | K28: =I28*J28*H28 -> 80000 | L28: NULL | N28: 61.70851855 | O28: 133.39233797 | P28: Моккуда | Q28: ЛБВУ ФАВР
A29: 27 | B29: =VLOOKUP(G29,ОКТМО!B:M,12,0) -> Мырыла | D29: Амга | E29: =VLOOKUP(G29,ОКТМО!B:M,6,0) -> Чурапчинский муниципальный район | F29: =VLOOKUP(G29,ОКТМО!B:M,12,0) -> Мырыла | G29: 98658435101 | H29: 2 | I29: 20 | J29: 4000 | K29: =I29*J29*H29 -> 160000 | L29: NULL | N29: 61.86336351 | O29: 133.67489259 | P29: Тэйэр Хайа | Q29: ЛБВУ ФАВР
A30: 28 | B30: =VLOOKUP(G30,ОКТМО!B:M,12,0) -> Чымнайи | D30: Амга | E30: =VLOOKUP(G30,ОКТМО!B:M,6,0) -> Таттинский муниципальный район | F30: =VLOOKUP(G30,ОКТМО!B:M,12,0) -> Чымнайи | G30: 98604460101 | H30: 2 | I30: 20 | J30: 2000 | K30: =I30*J30*H30 -> 80000 | L30: NULL | N30: 62.20163795 | O30: 134.68666475 | P30: о. Уодай | Q30: ЛБВУ ФАВР
A31: 29 | B31: =VLOOKUP(G31,ОКТМО!B:M,12,0) -> Орто-Нахара | D31: Нюя | E31: =VLOOKUP(G31,ОКТМО!B:M,6,0) -> Ленский муниципальный район | F31: =VLOOKUP(G31,ОКТМО!B:M,12,0) -> Орто-Нахара | G31: 98627433101 | H31: 2 | I31: 10 | J31: 1000 | K31: =I31*J31*H31 -> 20000 | L31: NULL | N31: 60.79993778 | O31: 114.43259638 | P31: в районе летника Киэнг-Юрях | Q31: ЛБВУ ФАВР
A32: 30 | B32: =VLOOKUP(G32,ОКТМО!B:M,12,0) -> Орто-Нахара | D32: Нюя | E32: =VLOOKUP(G32,ОКТМО!B:M,6,0) -> Ленский муниципальный район | F32: =VLOOKUP(G32,ОКТМО!B:M,12,0) -> Орто-Нахара | G32: 98627433101 | H32: 2 | I32: 10 | J32: 1000 | K32: =I32*J32*H32 -> 20000 | L32: NULL | N32: 60.82555406 | O32: 114.51568048 | P32: в районе МТФ «Захаровка» | Q32: ЛБВУ ФАВР
A33: 31 | B33: =VLOOKUP(G33,ОКТМО!B:M,12,0) -> Орто-Нахара | D33: Нюя | E33: =VLOOKUP(G33,ОКТМО!B:M,6,0) -> Ленский муниципальный район | F33: =VLOOKUP(G33,ОКТМО!B:M,12,0) -> Орто-Нахара | G33: 98627433101 | H33: 2 | I33: 10 | J33: 1000 | K33: =I33*J33*H33 -> 20000 | L33: NULL | N33: 60.82295988 | O33: 114.54091470 | P33: ниже участка №2 | Q33: ЛБВУ ФАВР
A34: 32 | B34: =VLOOKUP(G34,ОКТМО!B:M,12,0) -> Орто-Нахара | D34: Нюя | E34: =VLOOKUP(G34,ОКТМО!B:M,6,0) -> Ленский муниципальный район | F34: =VLOOKUP(G34,ОКТМО!B:M,12,0) -> Орто-Нахара | G34: 98627433101 | H34: 2 | I34: 10 | J34: 1000 | K34: =I34*J34*H34 -> 20000 | L34: NULL | N34: 60.81977963 | O34: 114.55928247 | P34: ниже участка №3 | Q34: ЛБВУ ФАВР
A35: 33 | B35: =VLOOKUP(G35,ОКТМО!B:M,12,0) -> Тяня | D35: Токко | E35: =VLOOKUP(G35,ОКТМО!B:M,6,0) -> Олекминский муниципальный район | F35: =VLOOKUP(G35,ОКТМО!B:M,12,0) -> Тяня | G35: 98641475101 | H35: 2 | I35: 20 | J35: 2000 | K35: =I35*J35*H35 -> 80000 | L35: NULL | N35: 59.07944229 | O35: 119.75873392 | P35: в 5,5 км от устья р. Тяня | Q35: ЛБВУ ФАВР
... A48: 46 | B48: =VLOOKUP(G48,ОКТМО!B:M,12,0) -> Якутск | D48: Лена | E48: =VLOOKUP(G48,ОКТМО!B:M,6,0) -> Городской округ Город Якутск | F48: =VLOOKUP(G48,ОКТМО!B:M,12,0) -> Якутск | G48: 98701000001 | H48: 3 | I48: 20 | J48: 1500 | K48: =I48*J48*H48 -> 90000 | L48: NULL | N48: 62.29527834 | O48: 130.07369440 | P48: Кангаласский мыс | Q48: ФИЛИАЛ "ЛЕНАРЕГИОНВОДХОЗ"
A49: 47 | B49: =VLOOKUP(G49,ОКТМО!B:M,12,0) -> Якутск | D49: Лена | E49: =VLOOKUP(G49,ОКТМО!B:M,6,0) -> Городской округ Город Якутск | F49: =VLOOKUP(G49,ОКТМО!B:M,12,0) -> Якутск | G49: 98701000001 | H49: NULL | I49: NULL | J49: 8000 | K49: NULL | L49: Распиловка | N49: 62.34439989 | O49: 130.05515497 | P49: Кангаласский мыс | Q49: ФИЛИАЛ "ЛЕНАРЕГИОНВОДХОЗ"
A50: 48 | B50: =VLOOKUP(G50,ОКТМО!B:M,12,0) -> Якутск | D50: Лена | E50: =VLOOKUP(G50,ОКТМО!B:M,6,0) -> Городской округ Город Якутск | F50: =VLOOKUP(G50,ОКТМО!B:M,12,0) -> Якутск | G50: 98701000001 | H50: 2 | I50: 20 | J50: 2000 | K50: =I50*J50*H50 -> 80000 | L50: NULL | N50: 62.36128680 | O50: 130.03730219 | P50: Кангаласский мыс | Q50: ФИЛИАЛ "ЛЕНАРЕГИОНВОДХОЗ"
A51: 49 | B51: =VLOOKUP(G51,ОКТМО!B:M,12,0) -> Ымыяхтах | D51: Лена | E51: =VLOOKUP(G51,ОКТМО!B:M,6,0) -> Намский муниципальный район | F51: =VLOOKUP(G51,ОКТМО!B:M,12,0) -> Ымыяхтах | G51: 98635415101 | H51: 3 | I51: 20 | J51: 3500 | K51: =I51*J51*H51 -> 210000 | L51: NULL | N51: 62.42889837 | O51: 129.98889368 | P51: у Буденновской протоки | Q51: ФИЛИАЛ "ЛЕНАРЕГИОНВОДХОЗ"
A52: 50 | B52: =VLOOKUP(G52,ОКТМО!B:M,12,0) -> Ымыяхтах | D52: Лена | E52: =VLOOKUP(G52,ОКТМО!B:M,6,0) -> Намский муниципальный район | F52: =VLOOKUP(G52,ОКТМО!B:M,12,0) -> Ымыяхтах | G52: 98635415101 | H52: NULL | I52: NULL | J52: 5000 | K52: NULL | L52: Распиловка | N52: 62.46145649 | O52: 129.98958032 | P52: у Буденновской протоки | Q52: ФИЛИАЛ "ЛЕНАРЕГИОНВОДХОЗ"
A53: 51 | B53: =VLOOKUP(G53,ОКТМО!B:M,12,0) -> Ымыяхтах | D53: Лена | E53: =VLOOKUP(G53,ОКТМО!B:M,6,0) -> Намский муниципальный район | F53: =VLOOKUP(G53,ОКТМО!B:M,12,0) -> Ымыяхтах | G53: 98635415101 | H53: NULL | I53: NULL | J53: 8000 | K53: NULL | L53: Распиловка | N53: 62.47954664 | O53: 129.99816339 | P53: у о. Делюсюннях | Q53: ФИЛИАЛ "ЛЕНАРЕГИОНВОДХОЗ"
...

Sheet Реестр_ЧС
A1: № п/п | B1: ЧС по характеру и виду источника возникновения, в соответствии с перечнем | C1: Дата, субъект РФ, место, краткое описание чрезвычайной ситуации, причина возникновения ЧС | D1: Уровень ЧС | E1: Количество погибших | F1: Количество пострадавших | G1: Количество пострадавших (в том числе - детей) | H1: Количество спасенных | I1: дата введения | J1: район | K1: Год | L1: Тип ЧС
A2: 1 | B2: 1.8. Аварии на коммунальных системах жизнеобеспечения | C2: 03.01.01г. в Алданском районе, г.Томмот, в результате выхода из строя двух сетевых насосов остановлена котельная МУП ЖКХ, слита вода из системы отопления из 20 жилых домов, 5 зданий соцкультбыта, 2000 м теплотрассы. Без тепла остались 180 человек, из них 40 детей. | D2: Муниципальный | F2: 180 | I2: 36894 | J2: Алданский муниципальный район | K2: =YEAR(I2) -> 2001 | L2: Аварии в отопительный сезон
A3: 2 | B3: 1.8. Аварии на коммунальных системах жизнеобеспечения | C3: 04.01.01г. в 23 час.00 мин.в Усть - Янском районе, п.Казачье, остановлена котельная ПАКУ из-за течи котла, второй котел не смогли запустить (работают котлы на нефти). Слита вода с 5 жилых домов и 14 частных домов, теплотрассы длиной 1,82 км., с контор ЖКП, здания администрации, конторы ГУП "Дьааана. | D3: Муниципальный | I3: 36895 | J3: Усть-Янский муниципальный район | K3: =YEAR(I3) -> 2001 | L3: Аварии в отопительный сезон
A4: 3 | B4: 1.2.5. Пожары в зданиях (сооружениях) жилого, административного, учебно - воспитательного, социального, культурно - досугового назначения, здравоохранения | C4: 10.01.01г. в 04 час. 21мин в Томпонском районе, п.Хандыга, по улице П.Алексеева,15, произошел пожар в жилом доме. На месте пожара обнаружено 2 трупа: гр.Гороховой Л.А -1932 г.р. - пенсионерка и гр.Кучина А.В - 1972 г. р.- БОМР. Причина, виновник, ущерб пожара устанавливается . | D4: Локальный | E4: 2 | I4: 36901 | J4: Томпонский муниципальный район | K4: =YEAR(I4) -> 2001 | L4: Техногенные пожары
A5: 4 | B5: 1.8. Аварии на коммунальных системах жизнеобеспечения | C5: 15.01.01г. в Ленском районе, г.Ленск, из-за сильной утечки воды на теплотрассе, остановлена подача тепла в жилые дома от котельной "Чапаево". В результате аварии слита вода с 46-ти жилых домов (из них 16 жил.д. и 30 част. д.). Проживает 670 чел, из них 180 дети. | D5: Федеральный | F5: 670 | G5: 180 | I5: 36906 | J5: Ленский муниципальный район | K5: =YEAR(I5) -> 2001 | L5: Аварии в отопительный сезон
A6: 5 | B6: 1.2.4. Пожары на транспортных средствах (в т.ч. железнодорожный, водный,автомобильный, воздушный транспорт) | C6: 22.01.01г. в 11 час.50 мин. в Аллайховском районе, п.Чокурдах при заправке газоконденсатом емкости бензовоза произошло воспламенение топлива. В результате взрыва уничтожена автомашина УРАЛ-5557 Муниципального управления ЖКХ. Водитель не пострадал. | D6: Локальный | E6: 2 | I6: 36913 | J6: Аллаиховский муниципальный район | K6: =YEAR(I6) -> 2001 | L6: Дорожно-транспортные происшествия, на водном транспорте, АСР
A7: 6 | B7: 1.2.5. Пожары в зданиях (сооружениях) жилого, административного, учебно - воспитательного, социального, культурно - досугового назначения, здравоохранения | C7: 28.01.01г. в 03 час.30 мин. в Кобяйском районе, с.Кобяйск, произошел пожар в жилом доме. Здание деревянное двухэтажное огнем унеч-тожено полностью. На месте пожара обнаружено 3 трупа: гр.Сметаниной Р. Н. - 1973 г.р., гр.Сметанина К.- 1990 г.р. и гр.Сметанина С.- 1994 г.р.Причина, виновник, ущерб пожара устанавливаются. | D7: Локальный | E7: 3 | I7: 36919 | J7: Кобяйский муниципальный район | K7: =YEAR(I7) -> 2001 | L7: Техногенные пожары
A8: 7 | B8: 1.2.1. Пожары в зданиях,сооружениях, установках (в т.ч. магистральные газо -, нефте -, продуктопроводы) производственного назначения. | C8: 02.02.01г. в 14 час. 20 мин. в Усть - Янском районе, п.Депутатский, произошел пожар в здании ДЭС ( 11 ДГ). Огнем уничтожен силовой кабель и все ДГ. Электрообеспечение поселка отсутствует. В результате пожара остановлена центральная котельная, обеспечивающая теплом 26 жил. домов и 33 объекта производственного соцкульбыта. Без тепла остались 3 698 чел. (из них 1 208 детей). Пострадавшие были эвакуированы в соседние населённые пункты и в г. Якутск. Причина НППБ при выполнении свар. работ. | D8: Федеральный | F8: 3698 | G8: 1208 | I8: 36924 | J8: Усть-Янский муниципальный район | K8: =YEAR(I8) -> 2001 | L8: Техногенные пожары
A9: 8 | B9: 1.8. Аварии на коммунальных системах жизнеобеспечения | C9: 03.02.01г. в 02 час. 22 мин. в Ленском районе, г.Ленск, в котельной "Школьная" на котле КСВД произошел разрыв передней водяной камеры и выброс пароводяной смеси. Пострадало 4 человека, доставлены в больницу, из них двое скончались. | D9: Локальный | E9: 2 | F9: 4 | I9: 36925 | J9: Ленский муниципальный район | K9: =YEAR(I9) -> 2001 | L9: Аварии в отопительный сезон
A10: 9 | B10: 1.2.5. Пожары в зданиях (сооружениях) жилого, административного, учебно - воспитательного, социального, культурно - досугового назначения, здравоохранения | C10: 04.02.01г. в 14 час.50 мин. в Алданском районе, п.Ленинский, по улице Ленина,51, произошел пожар в жилом доме. В результате пожара погибли 3 человека: гр.Разумовская В. М. – 1941 г.р., Косых А. Ф.- 1940 г.р. и Разумовский Ю. В. – 1945 г. р. Причина пожара – неосторожность при курении. | D10: Локальный | E10: 3 | I10: 36926 | J10: Алданский муниципальный район | K10: =YEAR(I10) -> 2001 | L10: Аварии в отопительный сезон
A11: 10 | B11: 1.2.5. Пожары в зданиях (сооружениях) жилого, административного, учебно - воспитательного, социального, культурно - досугового назначения, здравоохранения | C11: 09.02.01г. в 12час.24 мин. в Мирнинском районе, мкр.Романовка,13, произошел пожар в частном доме. Погибло 3 человека. | D11: Локальный | E11: 3 | I11: 36931 | J11: Мирнинский муниципальный район | K11: =YEAR(I11) -> 2001 | L11: Техногенные пожары
A12: 11 | B12: 1.8. Аварии на коммунальных системах жизнеобеспечения | C12: 15.02.01г. в 15час. 15мин. в Верхоянском районе, с.Сайды произошла авария в ДЭС. В результате аварии вода слита с теплотрасс с 57 жилых домов, в которых проживает 435 человек. | D12: Региональный | F12: 435 | I12: 36937 | J12: Верхоянский муниципальный район | K12: =YEAR(I12) -> 2001 | L12: Аварии в отопительный сезон
A13: 12 | B13: 1.2.1. Пожары в зданиях,сооружениях, установках (в т.ч. магистральные газо -, нефте -, продуктопроводы) производственного назначения. | C13: 15.02.01г. в 00ч.30мин. в Таттинском районе, с.Ытык - Кель произошел пожар в центральной котельной. В результате пожара пострадала правая часть здания.В результате пожара погиб гр.Попов В.Н. - 1956 г.р. - оператор. Без тепла остались 17 жилых дома (659 чел.), 7 производственных объектов. Пострадавшие расселены по родственникам и знакомым. | D13: Федеральный | E13: 1 | F13: 659 | I13: 36937 | J13: Таттинский муниципальный район | K13: =YEAR(I13) -> 2001 | L13: Техногенные пожары
A14: 13 | B14: 1.2.5. Пожары в зданиях (сооружениях) жилого, административного, учебно - воспитательного, социального, культурно - досугового назначения, здравоохранения | C14: 18.02.01г. в 05час.40мин.в Таттинском районе, с.Харбалах, произошел пожар в частном доме. В результате пожара дом уничтожен по всей площади. В результате пожара погибло 2 человека и пострадало 5 человек (из них 3 дети) (размещены по родственникам). | D14: Локальный | E14: 2 | F14: 5 | G14: 3 | I14: 36940 | J14: Таттинский муниципальный район | K14: =YEAR(I14) -> 2001 | L14: Техногенные пожары
A15: 14 | B15: 1.8. Аварии на коммунальных системах жизнеобеспечения | C15: 27.02.01г. в 21 час.08 мин. в Амгинском районе, с.Чыпчылган, произошел взрыв котла на квартальной котельной. В результате взрыва произошел пожар. Котельная отапливала 10 жилых домов, гранильную фабрику, здания школы, гараж, мед. пункт, АТС и библиотеку. Пострадавшие размещены по родственникам и знакомым. | D15: Муниципальный | I15: 36949 | J15: Амгинский муниципальный район | K15: =YEAR(I15) -> 2001 | L15: Аварии в отопительный сезон
A16: 15 | B16: 1.2.5. Пожары в зданиях (сооружениях) жилого, административного, учебно - воспитательного, социального, культурно - досугового назначения, здравоохранения | C16: 06.03.01г. В Алданском районе, г.Алдан, по улице Доставалова, произошел пожар в частном доме. В результате пожара погибло 2 человека. | D16: Локальный | E16: 2 | I16: 36956 | J16: Алданский муниципальный район | K16: =YEAR(I16) -> 2001 | L16: Техногенные пожары
A17: 16 | B17: 3.1.4. Отравления людей. | C17: 17.03.01г. в г.Якутске, по улице Ногина, 6, произошло отравление жидкостью "стеклоочистителем"( содержит метанол) в частном доме. В результате отравления погибли гр.Филиппов А.В. и гр.Власов А. Доставлены в тяжелом состоянии 2 человека в больницу. | D17: Локальный | E17: 2 | F17: 2 | I17: 36967 | J17: Городской округ Город Якутск | K17: =YEAR(I17) -> 2001 | L17: Отравления
A18: 17 | B18: 1.2.5. Пожары в зданиях (сооружениях) жилого, административного, учебно - воспитательного, социального, культурно - досугового назначения, здравоохранения | C18: 17.04.01г. в 02час.02мин. в п.Марха, произошел пожар в общежитии Мархинского завода строительных материалов и конструкций. В результате пожара огнем уничтожено общежитие по всей площади.В результате пожара погибло 2 человека и 3 человека доставлены в больницу с ожогами различной степени тяжести. | D18: Локальный | E18: 2 | F18: 3 | I18: 36998 | J18: Городской округ Город Якутск | K18: =YEAR(I18) -> 2001 | L18: Техногенные пожары
A19: 18 | B19: 1.2.5. Пожары в зданиях (сооружениях) жилого, административного, учебно - воспитательного, социального, культурно - досугового назначения, здравоохранения | C19: 18.04.01г. В 03 час.43 мин в Намском районе, с.Намцы, произошел пожар в частном доме. На месте пожара обнаружено 2 трупа: гр.Звонкова В. В.- БОМЖ. Личность второго погибшего устанавливается.Причина, ущерб, виновник пожара устанавливаются. | D19: Локальный | E19: 2 | I19: 36999 | J19: Намский муниципальный район | K19: =YEAR(I19) -> 2001 | L19: Техногенные пожары
A20: 19 | B20: 1.8. Аварии на коммунальных системах жизнеобеспечения | C20: 16.04.01г. в Усть - Майском орайоне, п.Эльдикан, произошло авария на системе теплоснабжения. В результате аварии произошло разморожение 17 объектов : из них 14 жил. домов, 2 административных зданий и 1 промышленный объект. | D20: Муниципальный | I20: 36997 | J20: Усть-Майский муниципальный район | K20: =YEAR(I20) -> 2001 | L20: Аварии в отопительный сезон
A21: 20 | B21: 1.2.5. Пожары в зданиях (сооружениях) жилого, административного, учебно - воспитательного, социального, культурно - досугового назначения, здравоохранения | C21: 03.07.01г. в Аллайховском районе, п.Чокурдах, произошёл пожар в жилом доме. В результате пожара огнем уничтожен дом по всей площади. В результате пожара погибло 2 человека и пострадало 98 человек Пострадавшие расселены по знакомым и родственниками. Причина пожара неосторожное обращение с огнем. (Детская шалость). Материальный ущерб составляет 4.345.071 руб. | D21: Локальный | E21: 2 | F21: 98 | I21: 37075 | J21: Аллаиховский муниципальный район | K21: =YEAR(I21) -> 2001 | L21: Техногенные пожары
A22: 21 | B22: 2.2.1. Оползни, обвалы, осыпи | C22: 18.08.01г. 23 час.00 мин. в Мирнинском районе, г.Мирный, в пионерском лагере «Орлёнок» пропали 3 девочки. В результате поисков были найдены в заваленной землей пещере в 100 м. от пионерского лагеря на беРегиональныйу реки Малая Ботуобуя. В результате принятых мер медиков по восстановлении жизнедеятельности детей положительного результата не дали. (Ахчыгнырова Женя – 1989 г.р., Иванова Анна – 1987 г.р., Малова Даша – 1992 г.р.) | D22: Локальный | E22: 3 | I22: 37121 | J22: Мирнинский муниципальный район | K22: =YEAR(I22) -> 2001 | L22: Разрушения дорожного полотна, моста
A23: 22 | B23: 1.1.3. - 1.1.4. Кораблекрушения, аварии, повреждения грузовых, пассажирских судов, судов атомного флота, маломерных судов и судов флота рыбной промышленности, повреждения судами беРегиональныйовых, гидротехнических и других объектов. | C23: 20.10.01. в Мирнинском районе, с.Сюлдюкюр, на реке Вилюй, в результате опрокидывания лодки утонули 2 человека: гр.Мингазов А.Г-1977г.р. и гр Дудников Ф.Н. - 1974 г.р. | D23: Локальный | E23: 2 | I23: 37184 | J23: Мирнинский муниципальный район | K23: =YEAR(I23) -> 2001 | L23: Дорожно-транспортные происшествия, на водном транспорте, АСР
A24: 23 | B24: 1.1.5. - 1.1.6. Авиационные и ракетно - космические катастрофы и аварии в аэропортах, на стартовых площадках и в населеных пунктах и вне аэропортов, стартовых площадок и населенных пунктов. | C24: 9.11.01г. в 09 час.42 мин. в Нерюнгринском районе, п.Чульман из аэропорта п.Чульман вылетел вертолет Ми-8 №27021 авиакомпании «Дельта-К», на боту находилось 11 человек включая экипаж и 1320 кг. груза. В назначенное время Ми-8 №27021 не вышел на связь. На поиск вертолета вылетел Ми-8 №22750. 11.11.01г. оперативной группой МЧС РС(Я) было найдено место крушение Ми-8 азимут-110 гр. Дальность-104 км. В результате осмотра место катастрофы обнаружено 11 трупов. | D24: Муниципальный | E24: 11 | I24: 37204 | J24: Нерюнгринский муниципальный район | K24: =YEAR(I24) -> 2001 | L24: Авиационные инциденты
A25: 24 | B25: 1.2.5. Пожары в зданиях (сооружениях) жилого, административного, учебно - воспитательного, социального, культурно - досугового назначения, здравоохранения | C25: 15.11.01г. в 20 час. 15 мин. в Верхоянском районе, п.Верхоянск, по ул. Бабушкина, 37, произошел пожар в жилом доме. В результате пожара дом уничтожен по всей площади. На месте пожара обнаружено три трупа (двое мужчин, одна женщина). | D25: Локальный | E25: 3 | I25: 37210 | J25: Верхоянский муниципальный район | K25: =YEAR(I25) -> 2001 | L25: Техногенные пожары
A26: 25 | B26: 1.1.8. Транспортные катастрофы и аварии на мостах, переправах, в тоннелях, горных вырабатках, на железнодорожных переездах. | C26: 24.11.01г. в Верхневилюйском районе, п.Верхневилюйск, при переправе через реку Вилюй провалились под лед и затонули две а\машины (УАЗ и ЗИЛ). В результате происшествия погибли 4 человека: гр. Иванов Д. М.- 1948 г. р., гр.Тихонов Н. В. - 1954 г. р., гр.Степанов Н. С. 1977 г. р. и гр.Сергеев Е. Е. 1972 г. р. | D26: Локальный | E26: 4 | I26: 37219 | J26: Верхневилюйский муниципальный район | K26: =YEAR(I26) -> 2001 | L26: Дорожно-транспортные происшествия, на водном транспорте, АСР
A27: 26 | B27: 1.2.1. Пожары в зданиях,сооружениях, установках (в т.ч. магистральные газо -, нефте -, продуктопроводы) производственного назначения. | C27: 17.01.02г. в 00 час.25 мин.в Ленском районе, п.Пеледуй, произошел пожар в котельной. Котельная принадлежит Пеледуйскому ССРЗ. В результате пожара уничтожено 10 тонн нефти, повреждена крыша насосной станции, вышло из строя 2 сетевых насоса. Получил ожоги различной степени тяжести грЯремский -ст.мастер смены доставлен в больницу. Без тепла остались 140 семей, промзона, дет.сад, профилакторий, музыкальная школа, старое здание школы. | D27: Региональный | F27: 420 | I27: 37273 | J27: Ленский муниципальный район | K27: =YEAR(I27) -> 2002 | L27: Техногенные пожары
A28: 27 | B28: 1.8. Аварии на коммунальных системах жизнеобеспечения | C28: 12.02.02 г. в 13ч.00 мин. в Нижнеколымском районе, п.Черский, прекращена подача электроэнергии от АО «Чукотэнерго», обесточены котельные. В 14ч.10 мин. подача электроэнергии подана на все объекты. После запуска котельных, котельную № 4 (сырая нефть) в рабочий режим ввести не удалось. Без тепла остались 30жилых домов, здания Сахателеком, больницы, школы, детсада ЖКХ . | D28: Муниципальный | I28: 37299 | J28: Нижнеколымский муниципальный район | K28: =YEAR(I28) -> 2002 | L28: Аварии в отопительный сезон
A29: 28 | B29: 1.2.1. Пожары в зданиях,сооружениях, установках (в т.ч. магистральные газо -, нефте -, продуктопроводы) производственного назначения. | C29: 22.09.02г. 21 час.30 мин. в Таттинском районе, с.Баяга, произошел пожар в квартальной котельной. В результате пожара огнем котельная уничтожено по всей площади.Без тепла остались контора местной администрации, дом культуры, почта, АТС, музшкола, ср.школа (240 учеников), мастерская школы, школьный музей (2 здания), гараж, начальная школа (84 ученика), спортзал, рынок. | D29: Региональный | F29: 324 | I29: 37521 | J29: Таттинский муниципальный район | K29: =YEAR(I29) -> 2002 | L29: Техногенные пожары
A30: 29 | B30: 1.8. Аварии на коммунальных системах жизнеобеспечения | C30: 28.11.02 в 15 час. 15 мин. в Алданском районе, п.Солнечный, из-за погодных условий произошло отключение электроэнергии подстанции № 5. Без электроэнергии остались котельные. В результате аварии без тепла остались 89 жилых дома, (2 300 чел.), детский сад, школа. 28.11.02.в 15ч. 45 мин. неисправность устранена, подана электроэнергия на все объекты | D30: Федеральный | F30: 2300 | I30: 37588 | J30: Алданский муниципальный район | K30: =YEAR(I30) -> 2002 | L30: Аварии в отопительный сезон
A31: 30 | B31: 1.8. Аварии на коммунальных системах жизнеобеспечения | C31: 30.11.02г. в 18 час. 00 мин. в Вилюйском районе, п.Кысыл - Сыр, из-за неисправности остановлен паровой котел в котельной. В результате аварии 2 водовода и 2 спутника длинной 300 м. были разморожены. Без тепла остались 937 квартир, где проживают 1200 человек. | D31: Федеральный | F31: 1200 | I31: 37590 | J31: Вилюйский муниципальный район | K31: =YEAR(I31) -> 2002 | L31: Аварии в отопительный сезон
A32: 31 | B32: 1.8. Аварии на коммунальных системах жизнеобеспечения | C32: 03.12.02г. в 18 час.24 мин. в Мирнинском районе, с.Таас - Юрях, произведена аварийная остановка котельной. В результате аварии без тепла остались школа,амбулатория, хлебопекарня, детсад,почта, здание администрации, магазина, клуб, около 80 жилых индивидуальных домов. В селе проживает 615 жителей. | D32: Федеральный | F32: 615 | I32: 37593 | J32: Мирнинский муниципальный район | K32: =YEAR(I32) -> 2002 | L32: Аварии в отопительный сезон
A33: 32 | B33: 1.8. Аварии на коммунальных системах жизнеобеспечения | C33: 06.12.02г. в Ленском районе, г.Ленск, из-за короткого замыкания силового кабеля в головной подстанции микрорайона «Мухтуя» были остановлены 4 котельные. В результате остановки котельных без тепла остались 11 жилых домов. 10.02.02г. с02 ч30 мин в котельной "Доярушка"прекращена подача воды по причине перемерзания водовода. Без тепла осталось 13 жилых домов ( 238 жильцов). | D33: Региональный | F33: 238 | I33: 37596 | J33: Ленский муниципальный район | K33: =YEAR(I33) -> 2002 | L33: Аварии в отопительный сезон
A34: 33 | B34: 1.8. Аварии на коммунальных системах жизнеобеспечения | C34: 19.12.02 г. в 14час. 30 мин. в г.Якутске на ЯГРЭС произошло аварийное отключение ГТУ №3 по причине «низкий уровень в демпферном баке ТГ-3». По автоматической разгрузке отключилась ВЛ –110 кВ Л - № 101. В резульате аварии остались без энергоснабжения: г. Якутск и его пригороды, улусы: Амгинский, Чурапчинский, Горный, Хангаласский, Намский, Мегино-Кангаласский, Усть-Алданский, Таттинский, Томпонский. В работе осталась только Якутская ТЭЦ. В 16ч. 40мин подано напряжение на объекты ГУП «Водоканал».С 16час. 55мин. проводилось постепенное подключение потребителей электроэнергии в г. Якутске.С 17ч. 20мин.подана электроэнергия в улусы: Горный, Хангаласский, Намский. В 18ч. 05мин подана электроэнергия до центров улусов: Амгинского, Чурапчинского, Мегино-Кангаласского, Усть-Алданского, Таттинского, Томпонского. | D34: Муниципальный | I34: 37609 | J34: Городской округ Город Якутск | K34: =YEAR(I34) -> 2002 | L34: Аварии в отопительный сезон
A35: 34 | B35: 1.2.1. Пожары в зданиях,сооружениях, установках (в т.ч. магистральные газо -, нефте -, продуктопроводы) производственного назначения. | C35: 01.01.03г. Таттинский район, с.Туора - Кель, произошел пожар в котельной. В результате пожара котельная уничтожена полностью. Котельная отапливала жилых домов, среднюю и начальную школу, сельский дом культуры. Нарушена жизнедеятельность 13 чел., в т.ч. 4 детей. Пострадавшее население размещено по родственникам и знакомым. | D35: Муниципальный | F35: 13 | I35: 37622 | J35: Таттинский муниципальный район | K35: =YEAR(I35) -> 2003 | L35: Техногенные пожары
A36: 35 | B36: 1.8. Аварии на коммунальных системах жизнеобеспечения | C36: 01.01.03г. Кобяйский район, с.Кобяй , в результате утечки бытового газа погибла семья из 6 человек: гр.Сметанин В.Н. -1964 г.р., гр.Сметанина М.Д.- 1964 г.р., гр.Сметанин Н.В. -1982г.р., гр.Сметанина Е.В.- 1993 г.р., гр.Сметанин А.В. -2001 г.р. и гр.Эверстов А.И.- 1989 г.р. | D36: Локальный | E36: 6/2 | I36: 37622 | J36: Кобяйский муниципальный район | K36: =YEAR(I36) -> 2003 | L36: Аварии в отопительный сезон
A37: 36 | B37: 3.1.4. Отравление людей | C37: 02.01.03г. в Среднеколымском районе, с.Сватай, произошло отравление антифризом. В результате отравления в ЦУБ г.Среднеколымска были направлены самолетом 7 несовершенолетних жителей, из них двое скончались в пути. По данным емкость с антифризом была найдена одним из подростков в гараже коллективного хозяйства “Сватайский”. В результате отравления погибли 2 человека: гр. Тырылгин А.С.-17 лет и гр.Антипин В.В.-14 лет. Пострадали 5 человек: гр.Колесов Д.Н.-17 лет, гр.Слепцов А.В.- 15 лет, гр.Павлов В.В.-15 лет, гр.Колесов С.Е.-14 лет, и гр.Оконешникова М.О.-17 лет. | D37: Локальный | E37: 2 | F37: 5 | I37: 37623 | J37: Среднеколымский муниципальный район | K37: =YEAR(I37) -> 2003 | L37: Отравления
A38: 37 | B38: 1.2.5. Пожары в зданиях (сооружениях) жилого, административного, учебно - воспитательного, социального, культурно - досугового назначения, здравоохранения | C38: 09.01.03г. в 05 час.05 мин. в Мегино - Кангаласском районе, с.Техтюр, произошел пожар в средней школе. В результате пожара школа уничтожена огнем по всей площади. Пострадавших нет. Ущерб 250 000 рублей. Причина, виновник устанавливается, возбуждено уголовное дело | D38: Локальный | I38: 37630 | J38: Мегино-Кангаласский муниципальный район | K38: =YEAR(I38) -> 2003 | L38: Техногенные пожары
A39: 38 | B39: 1.2.5. Пожары в зданиях (сооружениях) жилого, административного, учебно - воспитательного, социального, культурно - досугового назначения, здравоохранения | C39: 14.01.03г. в 09ч.10мин. в Алданском районе, п.Безымянный, по ул.Дорожная,7, произошел пожар частном доме. В результате пожара огнем уничтожен дом по всей площади. На месте пожара погибли гр.Чуб А. М. - 1936 г.р. и гр.Чуб Г.А. - 1964 г.р. Причина пожара – НППБ при эксплуатации электронагрева-тельных приборов. Виновник, ущерб устанавливаются. | D39: Локальный | E39: 2 | I39: 37635 | J39: Алданский муниципальный район | K39: =YEAR(I39) -> 2003 | L39: Техногенные пожары
A40: 39 | B40: 1.2.5. Пожары в зданиях (сооружениях) жилого, административного, учебно - воспитательного, социального, культурно - досугового назначения, здравоохранения | C40: 16.01.03г. в 07 час.14 мин. в Ленском районе, г.Ленск, по ул. Пролетарская, 55, произошел пожар в частном доме. В результате пожара уничтожена по всей площади стена и крыша дома. На месте пожара погибли 2 человека: гр.Комаров С.А.-1957 г.р. и гр.Ермакова Л.А. -1962 г.р. Трое пострадавших в состоянии средней тяжести доставлены в ЦРБ. На месте пожара работает СОГ. | D40: Локальный | E40: 2 | F40: 3 | I40: 37637 | J40: Ленский муниципальный район | K40: =YEAR(I40) -> 2003 | L40: Техногенные пожары
...

Sheet Анализ_ЧС
A1: Реестр чрезвычайных ситуаций с 2001 года | K1: ВСЕГО
A2: № | B2: Локальный | C2: Муниципальный | D2: Межмуниципальный | E2: Региональный | F2: Межрегиональный | G2: Федеральный | H2: ВСЕГО | J2: Природные ЧС | K2: =H56 -> 435
A3: 2001 | B3: =COUNTIFS(Реестр_ЧС!$D$2:$D$797,Анализ_ЧС!B$2,Реестр_ЧС!$K$2:$K$797,Анализ_ЧС!$A3) -> 16 | C3: =COUNTIFS(Реестр_ЧС!$D$2:$D$797,Анализ_ЧС!C$2,Реестр_ЧС!$K$2:$K$797,Анализ_ЧС!$A3) -> 5 | D3: =COUNTIFS(Реестр_ЧС!$D$2:$D$797,Анализ_ЧС!D$2,Реестр_ЧС!$K$2:$K$797,Анализ_ЧС!$A3) -> 0 | E3: =COUNTIFS(Реестр_ЧС!$D$2:$D$797,Анализ_ЧС!E$2,Реестр_ЧС!$K$2:$K$797,Анализ_ЧС!$A3) -> 1 | F3: =COUNTIFS(Реестр_ЧС!$D$2:$D$797,Анализ_ЧС!F$2,Реестр_ЧС!$K$2:$K$797,Анализ_ЧС!$A3) -> 0 | G3: =COUNTIFS(Реестр_ЧС!$D$2:$D$797,Анализ_ЧС!G$2,Реестр_ЧС!$K$2:$K$797,Анализ_ЧС!$A3) -> 3 | H3: =SUM(B3:G3) -> 25 | J3: Техногенные ЧС | K3: =M84 -> 262
A4: 2002 | B4: =COUNTIFS(Реестр_ЧС!$D$2:$D$797,Анализ_ЧС!B$2,Реестр_ЧС!$K$2:$K$797,Анализ_ЧС!$A4) -> 0 | C4: =COUNTIFS(Реестр_ЧС!$D$2:$D$797,Анализ_ЧС!C$2,Реестр_ЧС!$K$2:$K$797,Анализ_ЧС!$A4) -> 2 | D4: =COUNTIFS(Реестр_ЧС!$D$2:$D$797,Анализ_ЧС!D$2,Реестр_ЧС!$K$2:$K$797,Анализ_ЧС!$A4) -> 0 | E4: =COUNTIFS(Реестр_ЧС!$D$2:$D$797,Анализ_ЧС!E$2,Реестр_ЧС!$K$2:$K$797,Анализ_ЧС!$A4) -> 3 | F4: =COUNTIFS(Реестр_ЧС!$D$2:$D$797,Анализ_ЧС!F$2,Реестр_ЧС!$K$2:$K$797,Анализ_ЧС!$A4) -> 0 | G4: =COUNTIFS(Реестр_ЧС!$D$2:$D$797,Анализ_ЧС!G$2,Реестр_ЧС!$K$2:$K$797,Анализ_ЧС!$A4) -> 3 | H4: =SUM(B4:G4) -> 8 | J4: Биолого-соц ЧС | K4: =F112 -> 35
A5: 2003 | B5: =COUNTIFS(Реестр_ЧС!$D$2:$D$797,Анализ_ЧС!B$2,Реестр_ЧС!$K$2:$K$797,Анализ_ЧС!$A5) -> 13 | C5: =COUNTIFS(Реестр_ЧС!$D$2:$D$797,Анализ_ЧС!C$2,Реестр_ЧС!$K$2:$K$797,Анализ_ЧС!$A5) -> 6 | D5: =COUNTIFS(Реестр_ЧС!$D$2:$D$797,Анализ_ЧС!D$2,Реестр_ЧС!$K$2:$K$797,Анализ_ЧС!$A5) -> 0 | E5: =COUNTIFS(Реестр_ЧС!$D$2:$D$797,Анализ_ЧС!E$2,Реестр_ЧС!$K$2:$K$797,Анализ_ЧС!$A5) -> 2 | F5: =COUNTIFS(Реестр_ЧС!$D$2:$D$797,Анализ_ЧС!F$2,Реестр_ЧС!$K$2:$K$797,Анализ_ЧС!$A5) -> 0 | G5: =COUNTIFS(Реестр_ЧС!$D$2:$D$797,Анализ_ЧС!G$2,Реестр_ЧС!$K$2:$K$797,Анализ_ЧС!$A5) -> 0 | H5: =SUM(B5:G5) -> 21 | J5: Всего | K5: =K2+K3+K4 -> 732
A6: 2004 | B6: =COUNTIFS(Реестр_ЧС!$D$2:$D$797,Анализ_ЧС!B$2,Реестр_ЧС!$K$2:$K$797,Анализ_ЧС!$A6) -> 12 | C6: =COUNTIFS(Реестр_ЧС!$D$2:$D$797,Анализ_ЧС!C$2,Реестр_ЧС!$K$2:$K$797,Анализ_ЧС!$A6) -> 7 | D6: =COUNTIFS(Реестр_ЧС!$D$2:$D$797,Анализ_ЧС!D$2,Реестр_ЧС!$K$2:$K$797,Анализ_ЧС!$A6) -> 0 | E6: =COUNTIFS(Реестр_ЧС!$D$2:$D$797,Анализ_ЧС!E$2,Реестр_ЧС!$K$2:$K$797,Анализ_ЧС!$A6) -> 4 | F6: =COUNTIFS(Реестр_ЧС!$D$2:$D$797,Анализ_ЧС!F$2,Реестр_ЧС!$K$2:$K$797,Анализ_ЧС!$A6) -> 0 | G6: =COUNTIFS(Реестр_ЧС!$D$2:$D$797,Анализ_ЧС!G$2,Реестр_ЧС!$K$2:$K$797,Анализ_ЧС!$A6) -> 0 | H6: =SUM(B6:G6) -> 23
A7: 2005 | B7: =COUNTIFS(Реестр_ЧС!$D$2:$D$797,Анализ_ЧС!B$2,Реестр_ЧС!$K$2:$K$797,Анализ_ЧС!$A7) -> 26 | C7: =COUNTIFS(Реестр_ЧС!$D$2:$D$797,Анализ_ЧС!C$2,Реестр_ЧС!$K$2:$K$797,Анализ_ЧС!$A7) -> 4 | D7: =COUNTIFS(Реестр_ЧС!$D$2:$D$797,Анализ_ЧС!D$2,Реестр_ЧС!$K$2:$K$797,Анализ_ЧС!$A7) -> 0 | E7: =COUNTIFS(Реестр_ЧС!$D$2:$D$797,Анализ_ЧС!E$2,Реестр_ЧС!$K$2:$K$797,Анализ_ЧС!$A7) -> 1 | F7: =COUNTIFS(Реестр_ЧС!$D$2:$D$797,Анализ_ЧС!F$2,Реестр_ЧС!$K$2:$K$797,Анализ_ЧС!$A7) -> 0 | G7: =COUNTIFS(Реестр_ЧС!$D$2:$D$797,Анализ_ЧС!G$2,Реестр_ЧС!$K$2:$K$797,Анализ_ЧС!$A7) -> 0 | H7: =SUM(B7:G7) -> 31
A8: 2006 | B8: =COUNTIFS(Реестр_ЧС!$D$2:$D$797,Анализ_ЧС!B$2,Реестр_ЧС!$K$2:$K$797,Анализ_ЧС!$A8) -> 33 | C8: =COUNTIFS(Реестр_ЧС!$D$2:$D$797,Анализ_ЧС!C$2,Реестр_ЧС!$K$2:$K$797,Анализ_ЧС!$A8) -> 5 | D8: =COUNTIFS(Реестр_ЧС!$D$2:$D$797,Анализ_ЧС!D$2,Реестр_ЧС!$K$2:$K$797,Анализ_ЧС!$A8) -> 0 | E8: =COUNTIFS(Реестр_ЧС!$D$2:$D$797,Анализ_ЧС!E$2,Реестр_ЧС!$K$2:$K$797,Анализ_ЧС!$A8) -> 0 | F8: =COUNTIFS(Реестр_ЧС!$D$2:$D$797,Анализ_ЧС!F$2,Реестр_ЧС!$K$2:$K$797,Анализ_ЧС!$A8) -> 0 | G8: =COUNTIFS(Реестр_ЧС!$D$2:$D$797,Анализ_ЧС!G$2,Реестр_ЧС!$K$2:$K$797,Анализ_ЧС!$A8) -> 0 | H8: =SUM(B8:G8) -> 38
A9: 2007 | B9: =COUNTIFS(Реестр_ЧС!$D$2:$D$797,Анализ_ЧС!B$2,Реестр_ЧС!$K$2:$K$797,Анализ_ЧС!$A9) -> 0 | C9: =COUNTIFS(Реестр_ЧС!$D$2:$D$797,Анализ_ЧС!C$2,Реестр_ЧС!$K$2:$K$797,Анализ_ЧС!$A9) -> 0 | D9: =COUNTIFS(Реестр_ЧС!$D$2:$D$797,Анализ_ЧС!D$2,Реестр_ЧС!$K$2:$K$797,Анализ_ЧС!$A9) -> 0 | E9: =COUNTIFS(Реестр_ЧС!$D$2:$D$797,Анализ_ЧС!E$2,Реестр_ЧС!$K$2:$K$797,Анализ_ЧС!$A9) -> 0 | F9: =COUNTIFS(Реестр_ЧС!$D$2:$D$797,Анализ_ЧС!F$2,Реестр_ЧС!$K$2:$K$797,Анализ_ЧС!$A9) -> 0 | G9: =COUNTIFS(Реестр_ЧС!$D$2:$D$797,Анализ_ЧС!G$2,Реестр_ЧС!$K$2:$K$797,Анализ_ЧС!$A9) -> 0 | H9: =SUM(B9:G9) -> 0
A10: 2008 | B10: =COUNTIFS(Реестр_ЧС!$D$2:$D$797,Анализ_ЧС!B$2,Реестр_ЧС!$K$2:$K$797,Анализ_ЧС!$A10) -> 30 | C10: =COUNTIFS(Реестр_ЧС!$D$2:$D$797,Анализ_ЧС!C$2,Реестр_ЧС!$K$2:$K$797,Анализ_ЧС!$A10) -> 22 | D10: =COUNTIFS(Реестр_ЧС!$D$2:$D$797,Анализ_ЧС!D$2,Реестр_ЧС!$K$2:$K$797,Анализ_ЧС!$A10) -> 3 | E10: =COUNTIFS(Реестр_ЧС!$D$2:$D$797,Анализ_ЧС!E$2,Реестр_ЧС!$K$2:$K$797,Анализ_ЧС!$A10) -> 0 | F10: =COUNTIFS(Реестр_ЧС!$D$2:$D$797,Анализ_ЧС!F$2,Реестр_ЧС!$K$2:$K$797,Анализ_ЧС!$A10) -> 0 | G10: =COUNTIFS(Реестр_ЧС!$D$2:$D$797,Анализ_ЧС!G$2,Реестр_ЧС!$K$2:$K$797,Анализ_ЧС!$A10) -> 0 | H10: =SUM(B10:G10) -> 55
A11: 2009 | B11: =COUNTIFS(Реестр_ЧС!$D$2:$D$797,Анализ_ЧС!B$2,Реестр_ЧС!$K$2:$K$797,Анализ_ЧС!$A11) -> 0 | C11: =COUNTIFS(Реестр_ЧС!$D$2:$D$797,Анализ_ЧС!C$2,Реестр_ЧС!$K$2:$K$797,Анализ_ЧС!$A11) -> 2 | D11: =COUNTIFS(Реестр_ЧС!$D$2:$D$797,Анализ_ЧС!D$2,Реестр_ЧС!$K$2:$K$797,Анализ_ЧС!$A11) -> 0 | E11: =COUNTIFS(Реестр_ЧС!$D$2:$D$797,Анализ_ЧС!E$2,Реестр_ЧС!$K$2:$K$797,Анализ_ЧС!$A11) -> 0 | F11: =COUNTIFS(Реестр_ЧС!$D$2:$D$797,Анализ_ЧС!F$2,Реестр_ЧС!$K$2:$K$797,Анализ_ЧС!$A11) -> 0 | G11: =COUNTIFS(Реестр_ЧС!$D$2:$D$797,Анализ_ЧС!G$2,Реестр_ЧС!$K$2:$K$797,Анализ_ЧС!$A11) -> 0 | H11: =SUM(B11:G11) -> 2
A12: 2010 | B12: =COUNTIFS(Реестр_ЧС!$D$2:$D$797,Анализ_ЧС!B$2,Реестр_ЧС!$K$2:$K$797,Анализ_ЧС!$A12) -> 1 | C12: =COUNTIFS(Реестр_ЧС!$D$2:$D$797,Анализ_ЧС!C$2,Реестр_ЧС!$K$2:$K$797,Анализ_ЧС!$A12) -> 6 | D12: =COUNTIFS(Реестр_ЧС!$D$2:$D$797,Анализ_ЧС!D$2,Реестр_ЧС!$K$2:$K$797,Анализ_ЧС!$A12) -> 0 | E12: =COUNTIFS(Реестр_ЧС!$D$2:$D$797,Анализ_ЧС!E$2,Реестр_ЧС!$K$2:$K$797,Анализ_ЧС!$A12) -> 0 | F12: =COUNTIFS(Реестр_ЧС!$D$2:$D$797,Анализ_ЧС!F$2,Реестр_ЧС!$K$2:$K$797,Анализ_ЧС!$A12) -> 0 | G12: =COUNTIFS(Реестр_ЧС!$D$2:$D$797,Анализ_ЧС!G$2,Реестр_ЧС!$K$2:$K$797,Анализ_ЧС!$A12) -> 0 | H12: =SUM(B12:G12) -> 7
A13: 2011 | B13: =COUNTIFS(Реестр_ЧС!$D$2:$D$797,Анализ_ЧС!B$2,Реестр_ЧС!$K$2:$K$797,Анализ_ЧС!$A13) -> 0 | C13: =COUNTIFS(Реестр_ЧС!$D$2:$D$797,Анализ_ЧС!C$2,Реестр_ЧС!$K$2:$K$797,Анализ_ЧС!$A13) -> 5 | D13: =COUNTIFS(Реестр_ЧС!$D$2:$D$797,Анализ_ЧС!D$2,Реестр_ЧС!$K$2:$K$797,Анализ_ЧС!$A13) -> 1 | E13: =COUNTIFS(Реестр_ЧС!$D$2:$D$797,Анализ_ЧС!E$2,Реестр_ЧС!$K$2:$K$797,Анализ_ЧС!$A13) -> 1 | F13: =COUNTIFS(Реестр_ЧС!$D$2:$D$797,Анализ_ЧС!F$2,Реестр_ЧС!$K$2:$K$797,Анализ_ЧС!$A13) -> 0 | G13: =COUNTIFS(Реестр_ЧС!$D$2:$D$797,Анализ_ЧС!G$2,Реестр_ЧС!$K$2:$K$797,Анализ_ЧС!$A13) -> 0 | H13: =SUM(B13:G13) -> 7
A14: 2012 | B14: =COUNTIFS(Реестр_ЧС!$D$2:$D$797,Анализ_ЧС!B$2,Реестр_ЧС!$K$2:$K$797,Анализ_ЧС!$A14) -> 5 | C14: =COUNTIFS(Реестр_ЧС!$D$2:$D$797,Анализ_ЧС!C$2,Реестр_ЧС!$K$2:$K$797,Анализ_ЧС!$A14) -> 17 | D14: =COUNTIFS(Реестр_ЧС!$D$2:$D$797,Анализ_ЧС!D$2,Реестр_ЧС!$K$2:$K$797,Анализ_ЧС!$A14) -> 2 | E14: =COUNTIFS(Реестр_ЧС!$D$2:$D$797,Анализ_ЧС!E$2,Реестр_ЧС!$K$2:$K$797,Анализ_ЧС!$A14) -> 4 | F14: =COUNTIFS(Реестр_ЧС!$D$2:$D$797,Анализ_ЧС!F$2,Реестр_ЧС!$K$2:$K$797,Анализ_ЧС!$A14) -> 0 | G14: =COUNTIFS(Реестр_ЧС!$D$2:$D$797,Анализ_ЧС!G$2,Реестр_ЧС!$K$2:$K$797,Анализ_ЧС!$A14) -> 0 | H14: =SUM(B14:G14) -> 28
A15: 2013 | B15: =COUNTIFS(Реестр_ЧС!$D$2:$D$797,Анализ_ЧС!B$2,Реестр_ЧС!$K$2:$K$797,Анализ_ЧС!$A15) -> 0 | C15: =COUNTIFS(Реестр_ЧС!$D$2:$D$797,Анализ_ЧС!C$2,Реестр_ЧС!$K$2:$K$797,Анализ_ЧС!$A15) -> 7 | D15: =COUNTIFS(Реестр_ЧС!$D$2:$D$797,Анализ_ЧС!D$2,Реестр_ЧС!$K$2:$K$797,Анализ_ЧС!$A15) -> 3 | E15: =COUNTIFS(Реестр_ЧС!$D$2:$D$797,Анализ_ЧС!E$2,Реестр_ЧС!$K$2:$K$797,Анализ_ЧС!$A15) -> 6 | F15: =COUNTIFS(Реестр_ЧС!$D$2:$D$797,Анализ_ЧС!F$2,Реестр_ЧС!$K$2:$K$797,Анализ_ЧС!$A15) -> 0 | G15: =COUNTIFS(Реестр_ЧС!$D$2:$D$797,Анализ_ЧС!G$2,Реестр_ЧС!$K$2:$K$797,Анализ_ЧС!$A15) -> 0 | H15: =SUM(B15:G15) -> 16
A16: 2014 | B16: =COUNTIFS(Реестр_ЧС!$D$2:$D$797,Анализ_ЧС!B$2,Реестр_ЧС!$K$2:$K$797,Анализ_ЧС!$A16) -> 1 | C16: =COUNTIFS(Реестр_ЧС!$D$2:$D$797,Анализ_ЧС!C$2,Реестр_ЧС!$K$2:$K$797,Анализ_ЧС!$A16) -> 6 | D16: =COUNTIFS(Реестр_ЧС!$D$2:$D$797,Анализ_ЧС!D$2,Реестр_ЧС!$K$2:$K$797,Анализ_ЧС!$A16) -> 0 | E16: =COUNTIFS(Реестр_ЧС!$D$2:$D$797,Анализ_ЧС!E$2,Реестр_ЧС!$K$2:$K$797,Анализ_ЧС!$A16) -> 5 | F16: =COUNTIFS(Реестр_ЧС!$D$2:$D$797,Анализ_ЧС!F$2,Реестр_ЧС!$K$2:$K$797,Анализ_ЧС!$A16) -> 0 | G16: =COUNTIFS(Реестр_ЧС!$D$2:$D$797,Анализ_ЧС!G$2,Реестр_ЧС!$K$2:$K$797,Анализ_ЧС!$A16) -> 0 | H16: =SUM(B16:G16) -> 12
A17: 2015 | B17: =COUNTIFS(Реестр_ЧС!$D$2:$D$797,Анализ_ЧС!B$2,Реестр_ЧС!$K$2:$K$797,Анализ_ЧС!$A17) -> 3 | C17: =COUNTIFS(Реестр_ЧС!$D$2:$D$797,Анализ_ЧС!C$2,Реестр_ЧС!$K$2:$K$797,Анализ_ЧС!$A17) -> 3 | D17: =COUNTIFS(Реестр_ЧС!$D$2:$D$797,Анализ_ЧС!D$2,Реестр_ЧС!$K$2:$K$797,Анализ_ЧС!$A17) -> 0 | E17: =COUNTIFS(Реестр_ЧС!$D$2:$D$797,Анализ_ЧС!E$2,Реестр_ЧС!$K$2:$K$797,Анализ_ЧС!$A17) -> 0 | F17: =COUNTIFS(Реестр_ЧС!$D$2:$D$797,Анализ_ЧС!F$2,Реестр_ЧС!$K$2:$K$797,Анализ_ЧС!$A17) -> 0 | G17: =COUNTIFS(Реестр_ЧС!$D$2:$D$797,Анализ_ЧС!G$2,Реестр_ЧС!$K$2:$K$797,Анализ_ЧС!$A17) -> 0 | H17: =SUM(B17:G17) -> 6
... A20: 2018 | B20: =COUNTIFS(Реестр_ЧС!$D$2:$D$797,Анализ_ЧС!B$2,Реестр_ЧС!$K$2:$K$797,Анализ_ЧС!$A20) -> 1 | C20: =COUNTIFS(Реестр_ЧС!$D$2:$D$797,Анализ_ЧС!C$2,Реестр_ЧС!$K$2:$K$797,Анализ_ЧС!$A20) -> 65 | D20: =COUNTIFS(Реестр_ЧС!$D$2:$D$797,Анализ_ЧС!D$2,Реестр_ЧС!$K$2:$K$797,Анализ_ЧС!$A20) -> 5 | E20: =COUNTIFS(Реестр_ЧС!$D$2:$D$797,Анализ_ЧС!E$2,Реестр_ЧС!$K$2:$K$797,Анализ_ЧС!$A20) -> 9 | F20: =COUNTIFS(Реестр_ЧС!$D$2:$D$797,Анализ_ЧС!F$2,Реестр_ЧС!$K$2:$K$797,Анализ_ЧС!$A20) -> 0 | G20: =COUNTIFS(Реестр_ЧС!$D$2:$D$797,Анализ_ЧС!G$2,Реестр_ЧС!$K$2:$K$797,Анализ_ЧС!$A20) -> 1 | H20: =SUM(B20:G20) -> 81
A21: 2019 | B21: =COUNTIFS(Реестр_ЧС!$D$2:$D$797,Анализ_ЧС!B$2,Реестр_ЧС!$K$2:$K$797,Анализ_ЧС!$A21) -> 2 | C21: =COUNTIFS(Реестр_ЧС!$D$2:$D$797,Анализ_ЧС!C$2,Реестр_ЧС!$K$2:$K$797,Анализ_ЧС!$A21) -> 53 | D21: =COUNTIFS(Реестр_ЧС!$D$2:$D$797,Анализ_ЧС!D$2,Реестр_ЧС!$K$2:$K$797,Анализ_ЧС!$A21) -> 3 | E21: =COUNTIFS(Реестр_ЧС!$D$2:$D$797,Анализ_ЧС!E$2,Реестр_ЧС!$K$2:$K$797,Анализ_ЧС!$A21) -> 1 | F21: =COUNTIFS(Реестр_ЧС!$D$2:$D$797,Анализ_ЧС!F$2,Реестр_ЧС!$K$2:$K$797,Анализ_ЧС!$A21) -> 0 | G21: =COUNTIFS(Реестр_ЧС!$D$2:$D$797,Анализ_ЧС!G$2,Реестр_ЧС!$K$2:$K$797,Анализ_ЧС!$A21) -> 0 | H21: =SUM(B21:G21) -> 59 | J21: Кол-во ошибок | K21: =I28-K5 -> 2
A22: 2020 | B22: =COUNTIFS(Реестр_ЧС!$D$2:$D$797,Анализ_ЧС!B$2,Реестр_ЧС!$K$2:$K$797,Анализ_ЧС!$A22) -> 0 | C22: =COUNTIFS(Реестр_ЧС!$D$2:$D$797,Анализ_ЧС!C$2,Реестр_ЧС!$K$2:$K$797,Анализ_ЧС!$A22) -> 46 | D22: =COUNTIFS(Реестр_ЧС!$D$2:$D$797,Анализ_ЧС!D$2,Реестр_ЧС!$K$2:$K$797,Анализ_ЧС!$A22) -> 2 | E22: =COUNTIFS(Реестр_ЧС!$D$2:$D$797,Анализ_ЧС!E$2,Реестр_ЧС!$K$2:$K$797,Анализ_ЧС!$A22) -> 1 | F22: =COUNTIFS(Реестр_ЧС!$D$2:$D$797,Анализ_ЧС!F$2,Реестр_ЧС!$K$2:$K$797,Анализ_ЧС!$A22) -> 0 | G22: =COUNTIFS(Реестр_ЧС!$D$2:$D$797,Анализ_ЧС!G$2,Реестр_ЧС!$K$2:$K$797,Анализ_ЧС!$A22) -> 0 | H22: =SUM(B22:G22) -> 49
A23: 2021 | B23: =COUNTIFS(Реестр_ЧС!$D$2:$D$797,Анализ_ЧС!B$2,Реестр_ЧС!$K$2:$K$797,Анализ_ЧС!$A23) -> 0 | C23: =COUNTIFS(Реестр_ЧС!$D$2:$D$797,Анализ_ЧС!C$2,Реестр_ЧС!$K$2:$K$797,Анализ_ЧС!$A23) -> 45 | D23: =COUNTIFS(Реестр_ЧС!$D$2:$D$797,Анализ_ЧС!D$2,Реестр_ЧС!$K$2:$K$797,Анализ_ЧС!$A23) -> 0 | E23: =COUNTIFS(Реестр_ЧС!$D$2:$D$797,Анализ_ЧС!E$2,Реестр_ЧС!$K$2:$K$797,Анализ_ЧС!$A23) -> 3 | F23: =COUNTIFS(Реестр_ЧС!$D$2:$D$797,Анализ_ЧС!F$2,Реестр_ЧС!$K$2:$K$797,Анализ_ЧС!$A23) -> 1 | G23: =COUNTIFS(Реестр_ЧС!$D$2:$D$797,Анализ_ЧС!G$2,Реестр_ЧС!$K$2:$K$797,Анализ_ЧС!$A23) -> 0 | H23: =SUM(B23:G23) -> 49
A24: 2022 | B24: =COUNTIFS(Реестр_ЧС!$D$2:$D$797,Анализ_ЧС!B$2,Реестр_ЧС!$K$2:$K$797,Анализ_ЧС!$A24) -> 1 | C24: =COUNTIFS(Реестр_ЧС!$D$2:$D$797,Анализ_ЧС!C$2,Реестр_ЧС!$K$2:$K$797,Анализ_ЧС!$A24) -> 35 | D24: =COUNTIFS(Реестр_ЧС!$D$2:$D$797,Анализ_ЧС!D$2,Реестр_ЧС!$K$2:$K$797,Анализ_ЧС!$A24) -> 0 | E24: =COUNTIFS(Реестр_ЧС!$D$2:$D$797,Анализ_ЧС!E$2,Реестр_ЧС!$K$2:$K$797,Анализ_ЧС!$A24) -> 2 | F24: =COUNTIFS(Реестр_ЧС!$D$2:$D$797,Анализ_ЧС!F$2,Реестр_ЧС!$K$2:$K$797,Анализ_ЧС!$A24) -> 0 | G24: =COUNTIFS(Реестр_ЧС!$D$2:$D$797,Анализ_ЧС!G$2,Реестр_ЧС!$K$2:$K$797,Анализ_ЧС!$A24) -> 1 | H24: =SUM(B24:G24) -> 39
A25: 2023 | B25: =COUNTIFS(Реестр_ЧС!$D$2:$D$797,Анализ_ЧС!B$2,Реестр_ЧС!$K$2:$K$797,Анализ_ЧС!$A25) -> 1 | C25: =COUNTIFS(Реестр_ЧС!$D$2:$D$797,Анализ_ЧС!C$2,Реестр_ЧС!$K$2:$K$797,Анализ_ЧС!$A25) -> 31 | D25: =COUNTIFS(Реестр_ЧС!$D$2:$D$797,Анализ_ЧС!D$2,Реестр_ЧС!$K$2:$K$797,Анализ_ЧС!$A25) -> 0 | E25: =COUNTIFS(Реестр_ЧС!$D$2:$D$797,Анализ_ЧС!E$2,Реестр_ЧС!$K$2:$K$797,Анализ_ЧС!$A25) -> 1 | F25: =COUNTIFS(Реестр_ЧС!$D$2:$D$797,Анализ_ЧС!F$2,Реестр_ЧС!$K$2:$K$797,Анализ_ЧС!$A25) -> 1 | G25: =COUNTIFS(Реестр_ЧС!$D$2:$D$797,Анализ_ЧС!G$2,Реестр_ЧС!$K$2:$K$797,Анализ_ЧС!$A25) -> 0 | H25: =SUM(B25:G25) -> 34
A26: 2024 | B26: =COUNTIFS(Реестр_ЧС!$D$2:$D$797,Анализ_ЧС!B$2,Реестр_ЧС!$K$2:$K$797,Анализ_ЧС!$A26) -> 0 | C26: =COUNTIFS(Реестр_ЧС!$D$2:$D$797,Анализ_ЧС!C$2,Реестр_ЧС!$K$2:$K$797,Анализ_ЧС!$A26) -> 45 | D26: =COUNTIFS(Реестр_ЧС!$D$2:$D$797,Анализ_ЧС!D$2,Реестр_ЧС!$K$2:$K$797,Анализ_ЧС!$A26) -> 0 | E26: =COUNTIFS(Реестр_ЧС!$D$2:$D$797,Анализ_ЧС!E$2,Реестр_ЧС!$K$2:$K$797,Анализ_ЧС!$A26) -> 2 | F26: =COUNTIFS(Реестр_ЧС!$D$2:$D$797,Анализ_ЧС!F$2,Реестр_ЧС!$K$2:$K$797,Анализ_ЧС!$A26) -> 0 | G26: =COUNTIFS(Реестр_ЧС!$D$2:$D$797,Анализ_ЧС!G$2,Реестр_ЧС!$K$2:$K$797,Анализ_ЧС!$A26) -> 2 | H26: =SUM(B26:G26) -> 49
A27: 2025 | B27: =COUNTIFS(Реестр_ЧС!$D$2:$D$797,Анализ_ЧС!B$2,Реестр_ЧС!$K$2:$K$797,Анализ_ЧС!$A27) -> 2 | C27: =COUNTIFS(Реестр_ЧС!$D$2:$D$797,Анализ_ЧС!C$2,Реестр_ЧС!$K$2:$K$797,Анализ_ЧС!$A27) -> 21 | D27: =COUNTIFS(Реестр_ЧС!$D$2:$D$797,Анализ_ЧС!D$2,Реестр_ЧС!$K$2:$K$797,Анализ_ЧС!$A27) -> 0 | E27: =COUNTIFS(Реестр_ЧС!$D$2:$D$797,Анализ_ЧС!E$2,Реестр_ЧС!$K$2:$K$797,Анализ_ЧС!$A27) -> 1 | F27: =COUNTIFS(Реестр_ЧС!$D$2:$D$797,Анализ_ЧС!F$2,Реестр_ЧС!$K$2:$K$797,Анализ_ЧС!$A27) -> 0 | G27: =COUNTIFS(Реестр_ЧС!$D$2:$D$797,Анализ_ЧС!G$2,Реестр_ЧС!$K$2:$K$797,Анализ_ЧС!$A27) -> 0 | H27: =SUM(B27:G27) -> 24
A28: Итого | B28: =SUM(B3:B27) -> 153 | C28: =SUM(C3:C27) -> 497 | D28: =SUM(D3:D27) -> 20 | E28: =SUM(E3:E27) -> 49 | F28: =SUM(F3:F27) -> 2 | G28: =SUM(G3:G27) -> 11 | H28: =SUM(B3:G27) -> 732 | I28: 734 | J28: по нумерации Реестр_ЧС
A29: Реестр природных ЧС
B30: Весеннее половодье | C30: Неблагоприятные погодные условия | D30: Летне-осенний паводок | E30: Природные пожары | F30: Засуха | G30: Землетрясение | H30: ВСЕГО
A31: 2001 | B31: =COUNTIFS(Реестр_ЧС!$L$2:$L$797,Анализ_ЧС!B$30,Реестр_ЧС!$K$2:$K$797,Анализ_ЧС!$A31) -> 0 | C31: =COUNTIFS(Реестр_ЧС!$L$2:$L$797,Анализ_ЧС!C$30,Реестр_ЧС!$K$2:$K$797,Анализ_ЧС!$A31) -> 0 | D31: =COUNTIFS(Реестр_ЧС!$L$2:$L$797,Анализ_ЧС!D$30,Реестр_ЧС!$K$2:$K$797,Анализ_ЧС!$A31) -> 0 | E31: =COUNTIFS(Реестр_ЧС!$L$2:$L$797,Анализ_ЧС!E$30,Реестр_ЧС!$K$2:$K$797,Анализ_ЧС!$A31) -> 0 | F31: =COUNTIFS(Реестр_ЧС!$L$2:$L$797,Анализ_ЧС!F$30,Реестр_ЧС!$K$2:$K$797,Анализ_ЧС!$A31) -> 0 | G31: =COUNTIFS(Реестр_ЧС!$L$2:$L$797,Анализ_ЧС!G$30,Реестр_ЧС!$K$2:$K$797,Анализ_ЧС!$A31) -> 0 | H31: =SUM(B31:G31) -> 0
A32: 2002 | B32: =COUNTIFS(Реестр_ЧС!$L$2:$L$797,Анализ_ЧС!B$30,Реестр_ЧС!$K$2:$K$797,Анализ_ЧС!$A32) -> 0 | C32: =COUNTIFS(Реестр_ЧС!$L$2:$L$797,Анализ_ЧС!C$30,Реестр_ЧС!$K$2:$K$797,Анализ_ЧС!$A32) -> 0 | D32: =COUNTIFS(Реестр_ЧС!$L$2:$L$797,Анализ_ЧС!D$30,Реестр_ЧС!$K$2:$K$797,Анализ_ЧС!$A32) -> 0 | E32: =COUNTIFS(Реестр_ЧС!$L$2:$L$797,Анализ_ЧС!E$30,Реестр_ЧС!$K$2:$K$797,Анализ_ЧС!$A32) -> 0 | F32: =COUNTIFS(Реестр_ЧС!$L$2:$L$797,Анализ_ЧС!F$30,Реестр_ЧС!$K$2:$K$797,Анализ_ЧС!$A32) -> 0 | G32: =COUNTIFS(Реестр_ЧС!$L$2:$L$797,Анализ_ЧС!G$30,Реестр_ЧС!$K$2:$K$797,Анализ_ЧС!$A32) -> 0 | H32: =SUM(B32:G32) -> 0
A33: 2003 | B33: =COUNTIFS(Реестр_ЧС!$L$2:$L$797,Анализ_ЧС!B$30,Реестр_ЧС!$K$2:$K$797,Анализ_ЧС!$A33) -> 1 | C33: =COUNTIFS(Реестр_ЧС!$L$2:$L$797,Анализ_ЧС!C$30,Реестр_ЧС!$K$2:$K$797,Анализ_ЧС!$A33) -> 0 | D33: =COUNTIFS(Реестр_ЧС!$L$2:$L$797,Анализ_ЧС!D$30,Реестр_ЧС!$K$2:$K$797,Анализ_ЧС!$A33) -> 0 | E33: =COUNTIFS(Реестр_ЧС!$L$2:$L$797,Анализ_ЧС!E$30,Реестр_ЧС!$K$2:$K$797,Анализ_ЧС!$A33) -> 0 | F33: =COUNTIFS(Реестр_ЧС!$L$2:$L$797,Анализ_ЧС!F$30,Реестр_ЧС!$K$2:$K$797,Анализ_ЧС!$A33) -> 0 | G33: =COUNTIFS(Реестр_ЧС!$L$2:$L$797,Анализ_ЧС!G$30,Реестр_ЧС!$K$2:$K$797,Анализ_ЧС!$A33) -> 0 | H33: =SUM(B33:G33) -> 1
A34: 2004 | B34: =COUNTIFS(Реестр_ЧС!$L$2:$L$797,Анализ_ЧС!B$30,Реестр_ЧС!$K$2:$K$797,Анализ_ЧС!$A34) -> 0 | C34: =COUNTIFS(Реестр_ЧС!$L$2:$L$797,Анализ_ЧС!C$30,Реестр_ЧС!$K$2:$K$797,Анализ_ЧС!$A34) -> 0 | D34: =COUNTIFS(Реестр_ЧС!$L$2:$L$797,Анализ_ЧС!D$30,Реестр_ЧС!$K$2:$K$797,Анализ_ЧС!$A34) -> 5 | E34: =COUNTIFS(Реестр_ЧС!$L$2:$L$797,Анализ_ЧС!E$30,Реестр_ЧС!$K$2:$K$797,Анализ_ЧС!$A34) -> 1 | F34: =COUNTIFS(Реестр_ЧС!$L$2:$L$797,Анализ_ЧС!F$30,Реестр_ЧС!$K$2:$K$797,Анализ_ЧС!$A34) -> 0 | G34: =COUNTIFS(Реестр_ЧС!$L$2:$L$797,Анализ_ЧС!G$30,Реестр_ЧС!$K$2:$K$797,Анализ_ЧС!$A34) -> 0 | H34: =SUM(B34:G34) -> 6
A35: 2005 | B35: =COUNTIFS(Реестр_ЧС!$L$2:$L$797,Анализ_ЧС!B$30,Реестр_ЧС!$K$2:$K$797,Анализ_ЧС!$A35) -> 1 | C35: =COUNTIFS(Реестр_ЧС!$L$2:$L$797,Анализ_ЧС!C$30,Реестр_ЧС!$K$2:$K$797,Анализ_ЧС!$A35) -> 0 | D35: =COUNTIFS(Реестр_ЧС!$L$2:$L$797,Анализ_ЧС!D$30,Реестр_ЧС!$K$2:$K$797,Анализ_ЧС!$A35) -> 1 | E35: =COUNTIFS(Реестр_ЧС!$L$2:$L$797,Анализ_ЧС!E$30,Реестр_ЧС!$K$2:$K$797,Анализ_ЧС!$A35) -> 0 | F35: =COUNTIFS(Реестр_ЧС!$L$2:$L$797,Анализ_ЧС!F$30,Реестр_ЧС!$K$2:$K$797,Анализ_ЧС!$A35) -> 0 | G35: =COUNTIFS(Реестр_ЧС!$L$2:$L$797,Анализ_ЧС!G$30,Реестр_ЧС!$K$2:$K$797,Анализ_ЧС!$A35) -> 0 | H35: =SUM(B35:G35) -> 2
A36: 2006 | B36: =COUNTIFS(Реестр_ЧС!$L$2:$L$797,Анализ_ЧС!B$30,Реестр_ЧС!$K$2:$K$797,Анализ_ЧС!$A36) -> 0 | C36: =COUNTIFS(Реестр_ЧС!$L$2:$L$797,Анализ_ЧС!C$30,Реестр_ЧС!$K$2:$K$797,Анализ_ЧС!$A36) -> 1 | D36: =COUNTIFS(Реестр_ЧС!$L$2:$L$797,Анализ_ЧС!D$30,Реестр_ЧС!$K$2:$K$797,Анализ_ЧС!$A36) -> 2 | E36: =COUNTIFS(Реестр_ЧС!$L$2:$L$797,Анализ_ЧС!E$30,Реестр_ЧС!$K$2:$K$797,Анализ_ЧС!$A36) -> 0 | F36: =COUNTIFS(Реестр_ЧС!$L$2:$L$797,Анализ_ЧС!F$30,Реестр_ЧС!$K$2:$K$797,Анализ_ЧС!$A36) -> 0 | G36: =COUNTIFS(Реестр_ЧС!$L$2:$L$797,Анализ_ЧС!G$30,Реестр_ЧС!$K$2:$K$797,Анализ_ЧС!$A36) -> 3 | H36: =SUM(B36:G36) -> 6
A37: 2007 | B37: =COUNTIFS(Реестр_ЧС!$L$2:$L$797,Анализ_ЧС!B$30,Реестр_ЧС!$K$2:$K$797,Анализ_ЧС!$A37) -> 0 | C37: =COUNTIFS(Реестр_ЧС!$L$2:$L$797,Анализ_ЧС!C$30,Реестр_ЧС!$K$2:$K$797,Анализ_ЧС!$A37) -> 0 | D37: =COUNTIFS(Реестр_ЧС!$L$2:$L$797,Анализ_ЧС!D$30,Реестр_ЧС!$K$2:$K$797,Анализ_ЧС!$A37) -> 0 | E37: =COUNTIFS(Реестр_ЧС!$L$2:$L$797,Анализ_ЧС!E$30,Реестр_ЧС!$K$2:$K$797,Анализ_ЧС!$A37) -> 0 | F37: =COUNTIFS(Реестр_ЧС!$L$2:$L$797,Анализ_ЧС!F$30,Реестр_ЧС!$K$2:$K$797,Анализ_ЧС!$A37) -> 0 | G37: =COUNTIFS(Реестр_ЧС!$L$2:$L$797,Анализ_ЧС!G$30,Реестр_ЧС!$K$2:$K$797,Анализ_ЧС!$A37) -> 0 | H37: =SUM(B37:G37) -> 0
A38: 2008 | B38: =COUNTIFS(Реестр_ЧС!$L$2:$L$797,Анализ_ЧС!B$30,Реестр_ЧС!$K$2:$K$797,Анализ_ЧС!$A38) -> 7 | C38: =COUNTIFS(Реестр_ЧС!$L$2:$L$797,Анализ_ЧС!C$30,Реестр_ЧС!$K$2:$K$797,Анализ_ЧС!$A38) -> 0 | D38: =COUNTIFS(Реестр_ЧС!$L$2:$L$797,Анализ_ЧС!D$30,Реестр_ЧС!$K$2:$K$797,Анализ_ЧС!$A38) -> 1 | E38: =COUNTIFS(Реестр_ЧС!$L$2:$L$797,Анализ_ЧС!E$30,Реестр_ЧС!$K$2:$K$797,Анализ_ЧС!$A38) -> 1 | F38: =COUNTIFS(Реестр_ЧС!$L$2:$L$797,Анализ_ЧС!F$30,Реестр_ЧС!$K$2:$K$797,Анализ_ЧС!$A38) -> 0 | G38: =COUNTIFS(Реестр_ЧС!$L$2:$L$797,Анализ_ЧС!G$30,Реестр_ЧС!$K$2:$K$797,Анализ_ЧС!$A38) -> 0 | H38: =SUM(B38:G38) -> 9
A39: 2009 | B39: =COUNTIFS(Реестр_ЧС!$L$2:$L$797,Анализ_ЧС!B$30,Реестр_ЧС!$K$2:$K$797,Анализ_ЧС!$A39) -> 0 | C39: =COUNTIFS(Реестр_ЧС!$L$2:$L$797,Анализ_ЧС!C$30,Реестр_ЧС!$K$2:$K$797,Анализ_ЧС!$A39) -> 0 | D39: =COUNTIFS(Реестр_ЧС!$L$2:$L$797,Анализ_ЧС!D$30,Реестр_ЧС!$K$2:$K$797,Анализ_ЧС!$A39) -> 0 | E39: =COUNTIFS(Реестр_ЧС!$L$2:$L$797,Анализ_ЧС!E$30,Реестр_ЧС!$K$2:$K$797,Анализ_ЧС!$A39) -> 0 | F39: =COUNTIFS(Реестр_ЧС!$L$2:$L$797,Анализ_ЧС!F$30,Реестр_ЧС!$K$2:$K$797,Анализ_ЧС!$A39) -> 0 | G39: =COUNTIFS(Реестр_ЧС!$L$2:$L$797,Анализ_ЧС!G$30,Реестр_ЧС!$K$2:$K$797,Анализ_ЧС!$A39) -> 0 | H39: =SUM(B39:G39) -> 0
A40: 2010 | B40: =COUNTIFS(Реестр_ЧС!$L$2:$L$797,Анализ_ЧС!B$30,Реестр_ЧС!$K$2:$K$797,Анализ_ЧС!$A40) -> 5 | C40: =COUNTIFS(Реестр_ЧС!$L$2:$L$797,Анализ_ЧС!C$30,Реестр_ЧС!$K$2:$K$797,Анализ_ЧС!$A40) -> 0 | D40: =COUNTIFS(Реестр_ЧС!$L$2:$L$797,Анализ_ЧС!D$30,Реестр_ЧС!$K$2:$K$797,Анализ_ЧС!$A40) -> 0 | E40: =COUNTIFS(Реестр_ЧС!$L$2:$L$797,Анализ_ЧС!E$30,Реестр_ЧС!$K$2:$K$797,Анализ_ЧС!$A40) -> 0 | F40: =COUNTIFS(Реестр_ЧС!$L$2:$L$797,Анализ_ЧС!F$30,Реестр_ЧС!$K$2:$K$797,Анализ_ЧС!$A40) -> 0 | G40: =COUNTIFS(Реестр_ЧС!$L$2:$L$797,Анализ_ЧС!G$30,Реестр_ЧС!$K$2:$K$797,Анализ_ЧС!$A40) -> 0 | H40: =SUM(B40:G40) -> 5
A41: 2011 | B41: =COUNTIFS(Реестр_ЧС!$L$2:$L$797,Анализ_ЧС!B$30,Реестр_ЧС!$K$2:$K$797,Анализ_ЧС!$A41) -> 4 | C41: =COUNTIFS(Реестр_ЧС!$L$2:$L$797,Анализ_ЧС!C$30,Реестр_ЧС!$K$2:$K$797,Анализ_ЧС!$A41) -> 0 | D41: =COUNTIFS(Реестр_ЧС!$L$2:$L$797,Анализ_ЧС!D$30,Реестр_ЧС!$K$2:$K$797,Анализ_ЧС!$A41) -> 0 | E41: =COUNTIFS(Реестр_ЧС!$L$2:$L$797,Анализ_ЧС!E$30,Реестр_ЧС!$K$2:$K$797,Анализ_ЧС!$A41) -> 2 | F41: =COUNTIFS(Реестр_ЧС!$L$2:$L$797,Анализ_ЧС!F$30,Реестр_ЧС!$K$2:$K$797,Анализ_ЧС!$A41) -> 0 | G41: =COUNTIFS(Реестр_ЧС!$L$2:$L$797,Анализ_ЧС!G$30,Реестр_ЧС!$K$2:$K$797,Анализ_ЧС!$A41) -> 0 | H41: =SUM(B41:G41) -> 6
A42: 2012 | B42: =COUNTIFS(Реестр_ЧС!$L$2:$L$797,Анализ_ЧС!B$30,Реестр_ЧС!$K$2:$K$797,Анализ_ЧС!$A42) -> 10 | C42: =COUNTIFS(Реестр_ЧС!$L$2:$L$797,Анализ_ЧС!C$30,Реестр_ЧС!$K$2:$K$797,Анализ_ЧС!$A42) -> 0 | D42: =COUNTIFS(Реестр_ЧС!$L$2:$L$797,Анализ_ЧС!D$30,Реестр_ЧС!$K$2:$K$797,Анализ_ЧС!$A42) -> 1 | E42: =COUNTIFS(Реестр_ЧС!$L$2:$L$797,Анализ_ЧС!E$30,Реестр_ЧС!$K$2:$K$797,Анализ_ЧС!$A42) -> 12 | F42: =COUNTIFS(Реестр_ЧС!$L$2:$L$797,Анализ_ЧС!F$30,Реестр_ЧС!$K$2:$K$797,Анализ_ЧС!$A42) -> 0 | G42: =COUNTIFS(Реестр_ЧС!$L$2:$L$797,Анализ_ЧС!G$30,Реестр_ЧС!$K$2:$K$797,Анализ_ЧС!$A42) -> 0 | H42: =SUM(B42:G42) -> 23
...

Sheet Реестр_затопленных_домов
A1: Дата (дд.мм.гггг) | B1: Наименование реки | C1: Наименование района | D1: Наименование населенного пункта | E1: Район (проверка) | F1: Наслег (проверка) | G1: Н.п. измененный | H1: ОКТМО | I1: Тип дома (частный дом, многоквартирный дом) | J1: Адрес* | K1: Адрес* (по ФИАС) | L1: Уровень воды (значение уровня воды от пола дома), см | N1: Кол-во ошибок "#н/д" | O1: =COUNTIF(H:H,"#н/д") -> 0
